<sdf version='1.7'>
  <world name='default'>
    <plugin name='hello' filename='libhello.so'/>
    <light name='sun' type='directional'>
      <cast_shadows>1</cast_shadows>
      <pose>0 0 10 0 -0 0</pose>
      <diffuse>0.8 0.8 0.8 1</diffuse>
      <specular>0.2 0.2 0.2 1</specular>
      <attenuation>
        <range>1000</range>
        <constant>0.9</constant>
        <linear>0.01</linear>
        <quadratic>0.001</quadratic>
      </attenuation>
      <direction>-0.5 0.1 -0.9</direction>
      <spot>
        <inner_angle>0</inner_angle>
        <outer_angle>0</outer_angle>
        <falloff>0</falloff>
      </spot>
    </light>
    <model name='ground_plane'>
      <static>1</static>
      <link name='link'>
        <collision name='collision'>
          <geometry>
            <plane>
              <normal>0 0 1</normal>
              <size>100 100</size>
            </plane>
          </geometry>
          <surface>
            <contact>
              <collide_bitmask>65535</collide_bitmask>
              <ode/>
            </contact>
            <friction>
              <ode>
                <mu>100</mu>
                <mu2>50</mu2>
              </ode>
              <torsional>
                <ode/>
              </torsional>
            </friction>
            <bounce/>
          </surface>
          <max_contacts>10</max_contacts>
        </collision>
        <visual name='visual'>
          <cast_shadows>0</cast_shadows>
          <geometry>
            <plane>
              <normal>0 0 1</normal>
              <size>100 100</size>
            </plane>
          </geometry>
          <material>
            <script>
              <uri>file://media/materials/scripts/gazebo.material</uri>
              <name>Gazebo/Grey</name>
            </script>
          </material>
        </visual>
        <self_collide>0</self_collide>
        <enable_wind>0</enable_wind>
        <kinematic>0</kinematic>
      </link>
    </model>
    <gravity>0 0 -9.8</gravity>
    <magnetic_field>6e-06 2.3e-05 -4.2e-05</magnetic_field>
    <atmosphere type='adiabatic'/>
    <physics type='ode'>
      <max_step_size>0.001</max_step_size>
      <real_time_factor>1</real_time_factor>
      <real_time_update_rate>1000</real_time_update_rate>
    </physics>
    <scene>
      <ambient>0.4 0.4 0.4 1</ambient>
      <background>0.7 0.7 0.7 1</background>
      <shadows>1</shadows>
    </scene>
    <wind/>
    <spherical_coordinates>
      <surface_model>EARTH_WGS84</surface_model>
      <latitude_deg>0</latitude_deg>
      <longitude_deg>0</longitude_deg>
      <elevation>0</elevation>
      <heading_deg>0</heading_deg>
    </spherical_coordinates>
    <model name='Building'>
      <pose>1.94951 0.222588 0 0 -0 0</pose>
      <link name='Wall_10'>
        <pose>-0 4.925 0 0 -0 3.14159</pose>
        <visual name='Wall_10_Visual_0'>
          <pose>-4.74655 0 1.25 0 -0 0</pose>
          <geometry>
            <box>
              <size>0.506908 0.15 2.5</size>
            </box>
          </geometry>
          <material>
            <script>
              <uri>file://media/materials/scripts/gazebo.material</uri>
              <name>Gazebo/Bricks</name>
            </script>
            <ambient>1 1 1 1</ambient>
          </material>
          <meta>
            <layer>0</layer>
          </meta>
        </visual>
        <collision name='Wall_10_Collision_0'>
          <geometry>
            <box>
              <size>0.506908 0.15 2.5</size>
            </box>
          </geometry>
          <pose>-4.74655 0 1.25 0 -0 0</pose>
          <max_contacts>10</max_contacts>
          <surface>
            <contact>
              <ode/>
            </contact>
            <bounce/>
            <friction>
              <torsional>
                <ode/>
              </torsional>
              <ode/>
            </friction>
          </surface>
        </collision>
        <visual name='Wall_10_Visual_1'>
          <pose>0.253454 0 0.25 0 -0 0</pose>
          <geometry>
            <box>
              <size>9.49309 0.15 0.5</size>
            </box>
          </geometry>
          <material>
            <script>
              <uri>file://media/materials/scripts/gazebo.material</uri>
              <name>Gazebo/Bricks</name>
            </script>
            <ambient>1 1 1 1</ambient>
          </material>
          <meta>
            <layer>0</layer>
          </meta>
        </visual>
        <collision name='Wall_10_Collision_1'>
          <geometry>
            <box>
              <size>9.49309 0.15 0.5</size>
            </box>
          </geometry>
          <pose>0.253454 0 0.25 0 -0 0</pose>
          <max_contacts>10</max_contacts>
          <surface>
            <contact>
              <ode/>
            </contact>
            <bounce/>
            <friction>
              <torsional>
                <ode/>
              </torsional>
              <ode/>
            </friction>
          </surface>
        </collision>
        <visual name='Wall_10_Visual_2'>
          <pose>-0.778092 0 1.5 0 -0 0</pose>
          <geometry>
            <box>
              <size>2.63 0.15 2</size>
            </box>
          </geometry>
          <material>
            <script>
              <uri>file://media/materials/scripts/gazebo.material</uri>
              <name>Gazebo/Bricks</name>
            </script>
            <ambient>1 1 1 1</ambient>
          </material>
          <meta>
            <layer>0</layer>
          </meta>
        </visual>
        <collision name='Wall_10_Collision_2'>
          <geometry>
            <box>
              <size>2.63 0.15 2</size>
            </box>
          </geometry>
          <pose>-0.778092 0 1.5 0 -0 0</pose>
          <max_contacts>10</max_contacts>
          <surface>
            <contact>
              <ode/>
            </contact>
            <bounce/>
            <friction>
              <torsional>
                <ode/>
              </torsional>
              <ode/>
            </friction>
          </surface>
        </collision>
        <visual name='Wall_10_Visual_3'>
          <pose>3.96845 0 1.5 0 -0 0</pose>
          <geometry>
            <box>
              <size>2.06309 0.15 2</size>
            </box>
          </geometry>
          <material>
            <script>
              <uri>file://media/materials/scripts/gazebo.material</uri>
              <name>Gazebo/Bricks</name>
            </script>
            <ambient>1 1 1 1</ambient>
          </material>
          <meta>
            <layer>0</layer>
          </meta>
        </visual>
        <collision name='Wall_10_Collision_3'>
          <geometry>
            <box>
              <size>2.06309 0.15 2</size>
            </box>
          </geometry>
          <pose>3.96845 0 1.5 0 -0 0</pose>
          <max_contacts>10</max_contacts>
          <surface>
            <contact>
              <ode/>
            </contact>
            <bounce/>
            <friction>
              <torsional>
                <ode/>
              </torsional>
              <ode/>
            </friction>
          </surface>
        </collision>
        <visual name='Wall_10_Visual_4'>
          <pose>-3.29309 0 2.4 0 -0 0</pose>
          <geometry>
            <box>
              <size>2.4 0.15 0.2</size>
            </box>
          </geometry>
          <material>
            <script>
              <uri>file://media/materials/scripts/gazebo.material</uri>
              <name>Gazebo/Bricks</name>
            </script>
            <ambient>1 1 1 1</ambient>
          </material>
          <meta>
            <layer>0</layer>
          </meta>
        </visual>
        <collision name='Wall_10_Collision_4'>
          <geometry>
            <box>
              <size>2.4 0.15 0.2</size>
            </box>
          </geometry>
          <pose>-3.29309 0 2.4 0 -0 0</pose>
          <max_contacts>10</max_contacts>
          <surface>
            <contact>
              <ode/>
            </contact>
            <bounce/>
            <friction>
              <torsional>
                <ode/>
              </torsional>
              <ode/>
            </friction>
          </surface>
        </collision>
        <visual name='Wall_10_Visual_5'>
          <pose>1.73691 0 2.4 0 -0 0</pose>
          <geometry>
            <box>
              <size>2.4 0.15 0.2</size>
            </box>
          </geometry>
          <material>
            <script>
              <uri>file://media/materials/scripts/gazebo.material</uri>
              <name>Gazebo/Bricks</name>
            </script>
            <ambient>1 1 1 1</ambient>
          </material>
          <meta>
            <layer>0</layer>
          </meta>
        </visual>
        <collision name='Wall_10_Collision_5'>
          <geometry>
            <box>
              <size>2.4 0.15 0.2</size>
            </box>
          </geometry>
          <pose>1.73691 0 2.4 0 -0 0</pose>
          <max_contacts>10</max_contacts>
          <surface>
            <contact>
              <ode/>
            </contact>
            <bounce/>
            <friction>
              <torsional>
                <ode/>
              </torsional>
              <ode/>
            </friction>
          </surface>
        </collision>
        <self_collide>0</self_collide>
        <enable_wind>0</enable_wind>
        <kinematic>0</kinematic>
      </link>
      <link name='Wall_12'>
        <collision name='Wall_12_Collision'>
          <geometry>
            <box>
              <size>10 0.15 2.5</size>
            </box>
          </geometry>
          <pose>0 0 1.25 0 -0 0</pose>
          <max_contacts>10</max_contacts>
          <surface>
            <contact>
              <ode/>
            </contact>
            <bounce/>
            <friction>
              <torsional>
                <ode/>
              </torsional>
              <ode/>
            </friction>
          </surface>
        </collision>
        <visual name='Wall_12_Visual'>
          <pose>0 0 1.25 0 -0 0</pose>
          <geometry>
            <box>
              <size>10 0.15 2.5</size>
            </box>
          </geometry>
          <material>
            <script>
              <uri>file://media/materials/scripts/gazebo.material</uri>
              <name>Gazebo/Bricks</name>
            </script>
            <ambient>1 1 1 1</ambient>
          </material>
          <meta>
            <layer>0</layer>
          </meta>
        </visual>
        <pose>-4.925 -0 0 0 -0 1.5708</pose>
        <self_collide>0</self_collide>
        <enable_wind>0</enable_wind>
        <kinematic>0</kinematic>
      </link>
      <link name='Wall_22'>
        <pose>-3.0416 -2.72457 0 0 -0 0</pose>
        <visual name='Wall_22_Visual_0'>
          <pose>-1.27765 0 1.25 0 -0 0</pose>
          <geometry>
            <box>
              <size>1.19469 0.15 2.5</size>
            </box>
          </geometry>
          <material>
            <script>
              <uri>file://media/materials/scripts/gazebo.material</uri>
              <name>Gazebo/Grey</name>
            </script>
            <ambient>0.996078 0.47451 0.0196078 1</ambient>
          </material>
          <meta>
            <layer>0</layer>
          </meta>
        </visual>
        <collision name='Wall_22_Collision_0'>
          <geometry>
            <box>
              <size>1.19469 0.15 2.5</size>
            </box>
          </geometry>
          <pose>-1.27765 0 1.25 0 -0 0</pose>
          <max_contacts>10</max_contacts>
          <surface>
            <contact>
              <ode/>
            </contact>
            <bounce/>
            <friction>
              <torsional>
                <ode/>
              </torsional>
              <ode/>
            </friction>
          </surface>
        </collision>
        <visual name='Wall_22_Visual_1'>
          <pose>1.23734 0 1.25 0 -0 0</pose>
          <geometry>
            <box>
              <size>1.27531 0.15 2.5</size>
            </box>
          </geometry>
          <material>
            <script>
              <uri>file://media/materials/scripts/gazebo.material</uri>
              <name>Gazebo/Grey</name>
            </script>
            <ambient>0.996078 0.47451 0.0196078 1</ambient>
          </material>
          <meta>
            <layer>0</layer>
          </meta>
        </visual>
        <collision name='Wall_22_Collision_1'>
          <geometry>
            <box>
              <size>1.27531 0.15 2.5</size>
            </box>
          </geometry>
          <pose>1.23734 0 1.25 0 -0 0</pose>
          <max_contacts>10</max_contacts>
          <surface>
            <contact>
              <ode/>
            </contact>
            <bounce/>
            <friction>
              <torsional>
                <ode/>
              </torsional>
              <ode/>
            </friction>
          </surface>
        </collision>
        <visual name='Wall_22_Visual_2'>
          <pose>-0.040311 0 2.25 0 -0 0</pose>
          <geometry>
            <box>
              <size>1.28 0.15 0.5</size>
            </box>
          </geometry>
          <material>
            <script>
              <uri>file://media/materials/scripts/gazebo.material</uri>
              <name>Gazebo/Grey</name>
            </script>
            <ambient>0.996078 0.47451 0.0196078 1</ambient>
          </material>
          <meta>
            <layer>0</layer>
          </meta>
        </visual>
        <collision name='Wall_22_Collision_2'>
          <geometry>
            <box>
              <size>1.28 0.15 0.5</size>
            </box>
          </geometry>
          <pose>-0.040311 0 2.25 0 -0 0</pose>
          <max_contacts>10</max_contacts>
          <surface>
            <contact>
              <ode/>
            </contact>
            <bounce/>
            <friction>
              <torsional>
                <ode/>
              </torsional>
              <ode/>
            </friction>
          </surface>
        </collision>
        <self_collide>0</self_collide>
        <enable_wind>0</enable_wind>
        <kinematic>0</kinematic>
      </link>
      <link name='Wall_27'>
        <collision name='Wall_27_Collision'>
          <geometry>
            <box>
              <size>2.25 0.15 2.5</size>
            </box>
          </geometry>
          <pose>0 0 1.25 0 -0 0</pose>
          <max_contacts>10</max_contacts>
          <surface>
            <contact>
              <ode/>
            </contact>
            <bounce/>
            <friction>
              <torsional>
                <ode/>
              </torsional>
              <ode/>
            </friction>
          </surface>
        </collision>
        <visual name='Wall_27_Visual'>
          <pose>0 0 1.25 0 -0 0</pose>
          <geometry>
            <box>
              <size>2.25 0.15 2.5</size>
            </box>
          </geometry>
          <material>
            <script>
              <uri>file://media/materials/scripts/gazebo.material</uri>
              <name>Gazebo/Grey</name>
            </script>
            <ambient>0.996078 0.47451 0.0196078 1</ambient>
          </material>
          <meta>
            <layer>0</layer>
          </meta>
        </visual>
        <pose>-1.2416 -3.77457 0 0 -0 -1.5708</pose>
        <self_collide>0</self_collide>
        <enable_wind>0</enable_wind>
        <kinematic>0</kinematic>
      </link>
      <link name='Wall_29'>
        <collision name='Wall_29_Collision'>
          <geometry>
            <box>
              <size>5.5 0.15 2.5</size>
            </box>
          </geometry>
          <pose>0 0 1.25 0 -0 0</pose>
          <max_contacts>10</max_contacts>
          <surface>
            <contact>
              <ode/>
            </contact>
            <bounce/>
            <friction>
              <torsional>
                <ode/>
              </torsional>
              <ode/>
            </friction>
          </surface>
        </collision>
        <visual name='Wall_29_Visual'>
          <pose>0 0 1.25 0 -0 0</pose>
          <geometry>
            <box>
              <size>5.5 0.15 2.5</size>
            </box>
          </geometry>
          <material>
            <script>
              <uri>file://media/materials/scripts/gazebo.material</uri>
              <name>Gazebo/Grey</name>
            </script>
            <ambient>0.435294 0.796078 0.67451 1</ambient>
          </material>
          <meta>
            <layer>0</layer>
          </meta>
        </visual>
        <pose>-2.23191 1.66808 0 0 -0 0</pose>
        <self_collide>0</self_collide>
        <enable_wind>0</enable_wind>
        <kinematic>0</kinematic>
      </link>
      <link name='Wall_3'>
        <pose>-0 -4.925 0 0 -0 0</pose>
        <visual name='Wall_3_Visual_0'>
          <pose>-1.05345 0 1.25 0 -0 0</pose>
          <geometry>
            <box>
              <size>7.89309 0.15 2.5</size>
            </box>
          </geometry>
          <material>
            <script>
              <uri>file://media/materials/scripts/gazebo.material</uri>
              <name>Gazebo/Bricks</name>
            </script>
            <ambient>1 1 1 1</ambient>
          </material>
          <meta>
            <layer>0</layer>
          </meta>
        </visual>
        <collision name='Wall_3_Collision_0'>
          <geometry>
            <box>
              <size>7.89309 0.15 2.5</size>
            </box>
          </geometry>
          <pose>-1.05345 0 1.25 0 -0 0</pose>
          <max_contacts>10</max_contacts>
          <surface>
            <contact>
              <ode/>
            </contact>
            <bounce/>
            <friction>
              <torsional>
                <ode/>
              </torsional>
              <ode/>
            </friction>
          </surface>
        </collision>
        <visual name='Wall_3_Visual_1'>
          <pose>4.51155 0 1.25 0 -0 0</pose>
          <geometry>
            <box>
              <size>0.976908 0.15 2.5</size>
            </box>
          </geometry>
          <material>
            <script>
              <uri>file://media/materials/scripts/gazebo.material</uri>
              <name>Gazebo/Bricks</name>
            </script>
            <ambient>1 1 1 1</ambient>
          </material>
          <meta>
            <layer>0</layer>
          </meta>
        </visual>
        <collision name='Wall_3_Collision_1'>
          <geometry>
            <box>
              <size>0.976908 0.15 2.5</size>
            </box>
          </geometry>
          <pose>4.51155 0 1.25 0 -0 0</pose>
          <max_contacts>10</max_contacts>
          <surface>
            <contact>
              <ode/>
            </contact>
            <bounce/>
            <friction>
              <torsional>
                <ode/>
              </torsional>
              <ode/>
            </friction>
          </surface>
        </collision>
        <visual name='Wall_3_Visual_2'>
          <pose>3.45809 0 2.25 0 -0 0</pose>
          <geometry>
            <box>
              <size>1.13 0.15 0.5</size>
            </box>
          </geometry>
          <material>
            <script>
              <uri>file://media/materials/scripts/gazebo.material</uri>
              <name>Gazebo/Bricks</name>
            </script>
            <ambient>1 1 1 1</ambient>
          </material>
          <meta>
            <layer>0</layer>
          </meta>
        </visual>
        <collision name='Wall_3_Collision_2'>
          <geometry>
            <box>
              <size>1.13 0.15 0.5</size>
            </box>
          </geometry>
          <pose>3.45809 0 2.25 0 -0 0</pose>
          <max_contacts>10</max_contacts>
          <surface>
            <contact>
              <ode/>
            </contact>
            <bounce/>
            <friction>
              <torsional>
                <ode/>
              </torsional>
              <ode/>
            </friction>
          </surface>
        </collision>
        <self_collide>0</self_collide>
        <enable_wind>0</enable_wind>
        <kinematic>0</kinematic>
      </link>
      <link name='Wall_31'>
        <collision name='Wall_31_Collision'>
          <geometry>
            <box>
              <size>2.25 0.15 2.5</size>
            </box>
          </geometry>
          <pose>0 0 1.25 0 -0 0</pose>
          <max_contacts>10</max_contacts>
          <surface>
            <contact>
              <ode/>
            </contact>
            <bounce/>
            <friction>
              <torsional>
                <ode/>
              </torsional>
              <ode/>
            </friction>
          </surface>
        </collision>
        <visual name='Wall_31_Visual'>
          <pose>0 0 1.25 0 -0 0</pose>
          <geometry>
            <box>
              <size>2.25 0.15 2.5</size>
            </box>
          </geometry>
          <material>
            <script>
              <uri>file://media/materials/scripts/gazebo.material</uri>
              <name>Gazebo/Grey</name>
            </script>
            <ambient>0.435294 0.796078 0.67451 1</ambient>
          </material>
          <meta>
            <layer>0</layer>
          </meta>
        </visual>
        <pose>0.443092 0.618082 0 0 -0 -1.5708</pose>
        <self_collide>0</self_collide>
        <enable_wind>0</enable_wind>
        <kinematic>0</kinematic>
      </link>
      <link name='Wall_34'>
        <pose>0.443092 3.21808 0 0 -0 1.5708</pose>
        <visual name='Wall_34_Visual_0'>
          <pose>-1.11 0 1.25 0 -0 0</pose>
          <geometry>
            <box>
              <size>1.03 0.15 2.5</size>
            </box>
          </geometry>
          <material>
            <script>
              <uri>file://media/materials/scripts/gazebo.material</uri>
              <name>Gazebo/Grey</name>
            </script>
            <ambient>0.435294 0.796078 0.67451 1</ambient>
          </material>
          <meta>
            <layer>0</layer>
          </meta>
        </visual>
        <collision name='Wall_34_Collision_0'>
          <geometry>
            <box>
              <size>1.03 0.15 2.5</size>
            </box>
          </geometry>
          <pose>-1.11 0 1.25 0 -0 0</pose>
          <max_contacts>10</max_contacts>
          <surface>
            <contact>
              <ode/>
            </contact>
            <bounce/>
            <friction>
              <torsional>
                <ode/>
              </torsional>
              <ode/>
            </friction>
          </surface>
        </collision>
        <visual name='Wall_34_Visual_1'>
          <pose>1.095 0 1.25 0 -0 0</pose>
          <geometry>
            <box>
              <size>1.06 0.15 2.5</size>
            </box>
          </geometry>
          <material>
            <script>
              <uri>file://media/materials/scripts/gazebo.material</uri>
              <name>Gazebo/Grey</name>
            </script>
            <ambient>0.435294 0.796078 0.67451 1</ambient>
          </material>
          <meta>
            <layer>0</layer>
          </meta>
        </visual>
        <collision name='Wall_34_Collision_1'>
          <geometry>
            <box>
              <size>1.06 0.15 2.5</size>
            </box>
          </geometry>
          <pose>1.095 0 1.25 0 -0 0</pose>
          <max_contacts>10</max_contacts>
          <surface>
            <contact>
              <ode/>
            </contact>
            <bounce/>
            <friction>
              <torsional>
                <ode/>
              </torsional>
              <ode/>
            </friction>
          </surface>
        </collision>
        <visual name='Wall_34_Visual_2'>
          <pose>-0.015 0 2.25 0 -0 0</pose>
          <geometry>
            <box>
              <size>1.16 0.15 0.5</size>
            </box>
          </geometry>
          <material>
            <script>
              <uri>file://media/materials/scripts/gazebo.material</uri>
              <name>Gazebo/Grey</name>
            </script>
            <ambient>0.435294 0.796078 0.67451 1</ambient>
          </material>
          <meta>
            <layer>0</layer>
          </meta>
        </visual>
        <collision name='Wall_34_Collision_2'>
          <geometry>
            <box>
              <size>1.16 0.15 0.5</size>
            </box>
          </geometry>
          <pose>-0.015 0 2.25 0 -0 0</pose>
          <max_contacts>10</max_contacts>
          <surface>
            <contact>
              <ode/>
            </contact>
            <bounce/>
            <friction>
              <torsional>
                <ode/>
              </torsional>
              <ode/>
            </friction>
          </surface>
        </collision>
        <self_collide>0</self_collide>
        <enable_wind>0</enable_wind>
        <kinematic>0</kinematic>
      </link>
      <link name='Wall_8'>
        <pose>4.925 -0 0 0 -0 1.5708</pose>
        <visual name='Wall_8_Visual_0'>
          <pose>-2.96129 0 1.25 0 -0 0</pose>
          <geometry>
            <box>
              <size>4.07741 0.15 2.5</size>
            </box>
          </geometry>
          <material>
            <script>
              <uri>file://media/materials/scripts/gazebo.material</uri>
              <name>Gazebo/Bricks</name>
            </script>
            <ambient>1 1 1 1</ambient>
          </material>
          <meta>
            <layer>0</layer>
          </meta>
        </visual>
        <collision name='Wall_8_Collision_0'>
          <geometry>
            <box>
              <size>4.07741 0.15 2.5</size>
            </box>
          </geometry>
          <pose>-2.96129 0 1.25 0 -0 0</pose>
          <max_contacts>10</max_contacts>
          <surface>
            <contact>
              <ode/>
            </contact>
            <bounce/>
            <friction>
              <torsional>
                <ode/>
              </torsional>
              <ode/>
            </friction>
          </surface>
        </collision>
        <visual name='Wall_8_Visual_1'>
          <pose>2.03871 0 0.25 0 -0 0</pose>
          <geometry>
            <box>
              <size>5.92259 0.15 0.5</size>
            </box>
          </geometry>
          <material>
            <script>
              <uri>file://media/materials/scripts/gazebo.material</uri>
              <name>Gazebo/Bricks</name>
            </script>
            <ambient>1 1 1 1</ambient>
          </material>
          <meta>
            <layer>0</layer>
          </meta>
        </visual>
        <collision name='Wall_8_Collision_1'>
          <geometry>
            <box>
              <size>5.92259 0.15 0.5</size>
            </box>
          </geometry>
          <pose>2.03871 0 0.25 0 -0 0</pose>
          <max_contacts>10</max_contacts>
          <surface>
            <contact>
              <ode/>
            </contact>
            <bounce/>
            <friction>
              <torsional>
                <ode/>
              </torsional>
              <ode/>
            </friction>
          </surface>
        </collision>
        <visual name='Wall_8_Visual_2'>
          <pose>3.23871 0 1.5 0 -0 0</pose>
          <geometry>
            <box>
              <size>3.52259 0.15 2</size>
            </box>
          </geometry>
          <material>
            <script>
              <uri>file://media/materials/scripts/gazebo.material</uri>
              <name>Gazebo/Bricks</name>
            </script>
            <ambient>1 1 1 1</ambient>
          </material>
          <meta>
            <layer>0</layer>
          </meta>
        </visual>
        <collision name='Wall_8_Collision_2'>
          <geometry>
            <box>
              <size>3.52259 0.15 2</size>
            </box>
          </geometry>
          <pose>3.23871 0 1.5 0 -0 0</pose>
          <max_contacts>10</max_contacts>
          <surface>
            <contact>
              <ode/>
            </contact>
            <bounce/>
            <friction>
              <torsional>
                <ode/>
              </torsional>
              <ode/>
            </friction>
          </surface>
        </collision>
        <visual name='Wall_8_Visual_3'>
          <pose>0.277413 0 2.4 0 -0 0</pose>
          <geometry>
            <box>
              <size>2.4 0.15 0.2</size>
            </box>
          </geometry>
          <material>
            <script>
              <uri>file://media/materials/scripts/gazebo.material</uri>
              <name>Gazebo/Bricks</name>
            </script>
            <ambient>1 1 1 1</ambient>
          </material>
          <meta>
            <layer>0</layer>
          </meta>
        </visual>
        <collision name='Wall_8_Collision_3'>
          <geometry>
            <box>
              <size>2.4 0.15 0.2</size>
            </box>
          </geometry>
          <pose>0.277413 0 2.4 0 -0 0</pose>
          <max_contacts>10</max_contacts>
          <surface>
            <contact>
              <ode/>
            </contact>
            <bounce/>
            <friction>
              <torsional>
                <ode/>
              </torsional>
              <ode/>
            </friction>
          </surface>
        </collision>
        <self_collide>0</self_collide>
        <enable_wind>0</enable_wind>
        <kinematic>0</kinematic>
      </link>
      <static>1</static>
    </model>
    <state world_name='default'>
      <sim_time>1671 837000000</sim_time>
      <real_time>46 2465730</real_time>
      <wall_time>1750961411 487188417</wall_time>
      <iterations>44952</iterations>
      <model name='Building'>
        <pose>1.94951 0.22259 0 0 -0 0</pose>
        <scale>1 1 1</scale>
        <link name='Wall_10'>
          <pose>1.94951 5.14759 0 0 -0 3.14159</pose>
          <velocity>0 0 0 0 -0 0</velocity>
          <acceleration>0 0 0 0 -0 0</acceleration>
          <wrench>0 0 0 0 -0 0</wrench>
        </link>
        <link name='Wall_12'>
          <pose>-2.97549 0.222588 0 0 -0 1.5708</pose>
          <velocity>0 0 0 0 -0 0</velocity>
          <acceleration>0 0 0 0 -0 0</acceleration>
          <wrench>0 0 0 0 -0 0</wrench>
        </link>
        <link name='Wall_22'>
          <pose>-1.09209 -2.50198 0 0 -0 0</pose>
          <velocity>0 0 0 0 -0 0</velocity>
          <acceleration>0 0 0 0 -0 0</acceleration>
          <wrench>0 0 0 0 -0 0</wrench>
        </link>
        <link name='Wall_27'>
          <pose>0.70791 -3.55198 0 0 0 -1.5708</pose>
          <velocity>0 0 0 0 -0 0</velocity>
          <acceleration>0 0 0 0 -0 0</acceleration>
          <wrench>0 0 0 0 -0 0</wrench>
        </link>
        <link name='Wall_29'>
          <pose>-0.2824 1.89067 0 0 -0 0</pose>
          <velocity>0 0 0 0 -0 0</velocity>
          <acceleration>0 0 0 0 -0 0</acceleration>
          <wrench>0 0 0 0 -0 0</wrench>
        </link>
        <link name='Wall_3'>
          <pose>1.94951 -4.70241 0 0 -0 0</pose>
          <velocity>0 0 0 0 -0 0</velocity>
          <acceleration>0 0 0 0 -0 0</acceleration>
          <wrench>0 0 0 0 -0 0</wrench>
        </link>
        <link name='Wall_31'>
          <pose>2.3926 0.84067 0 0 0 -1.5708</pose>
          <velocity>0 0 0 0 -0 0</velocity>
          <acceleration>0 0 0 0 -0 0</acceleration>
          <wrench>0 0 0 0 -0 0</wrench>
        </link>
        <link name='Wall_34'>
          <pose>2.3926 3.44067 0 0 -0 1.5708</pose>
          <velocity>0 0 0 0 -0 0</velocity>
          <acceleration>0 0 0 0 -0 0</acceleration>
          <wrench>0 0 0 0 -0 0</wrench>
        </link>
        <link name='Wall_8'>
          <pose>6.87451 0.222588 0 0 -0 1.5708</pose>
          <velocity>0 0 0 0 -0 0</velocity>
          <acceleration>0 0 0 0 -0 0</acceleration>
          <wrench>0 0 0 0 -0 0</wrench>
        </link>
      </model>
      <model name='Robot'>
        <pose>3.89636 -1.61134 0.21346 4e-06 1.1e-05 0.00207</pose>
        <scale>1 1 1</scale>
        <link name='link_0'>
          <pose>4.08226 -1.67025 0.2 4e-06 1.1e-05 0.00207</pose>
          <velocity>0.001692 -0.000569 -0.004908 0.004887 0.012477 0.001105</velocity>
          <acceleration>0.590732 -0.837966 -5.01142 -0.057279 1.28073 1.14362</acceleration>
          <wrench>0.590732 -0.837966 -5.01142 0 -0 0</wrench>
        </link>
        <link name='link_1'>
          <pose>3.78299 -2.02089 0.200002 1.57069 -0.515171 0.002122</pose>
          <velocity>0.002076 -0.000921 -0.002893 0.004876 0.005457 0.001109</velocity>
          <acceleration>0.989636 -1.19324 -3.04687 -0.043998 0.013021 0.98495</acceleration>
          <wrench>0.989636 -1.19324 -3.04687 0 -0 0</wrench>
        </link>
        <link name='link_1_clone'>
          <pose>4.38299 -2.01965 0.199995 1.5707 0.061735 0.002064</pose>
          <velocity>0.00209 -0.000262 -0.01037 0.004848 0.008118 0.00112</velocity>
          <acceleration>1.00123 -0.484748 -11.341 -0.028495 0.013054 0.997149</acceleration>
          <wrench>1.00123 -0.484748 -11.341 0 -0 0</wrench>
        </link>
        <link name='link_1_clone_0'>
          <pose>3.78154 -1.32085 0.200005 1.57069 -0.54726 0.002126</pose>
          <velocity>0.001302 -0.00096 0.000573 0.004809 0.006227 0.001146</velocity>
          <acceleration>0.216927 -1.26213 1.33848 -0.137153 -0.892167 0.989877</acceleration>
          <wrench>0.216927 -1.26213 1.33848 0 -0 0</wrench>
        </link>
        <link name='link_1_clone_1'>
          <pose>4.38154 -1.31961 0.199998 1.5707 -0.12697 0.002082</pose>
          <velocity>0.001314 -0.000225 -0.006896 0.004908 0.005614 0.001113</velocity>
          <acceleration>0.195158 -0.491505 -6.97617 -0.03994 0.013028 0.971944</acceleration>
          <wrench>0.195158 -0.491505 -6.97617 0 -0 0</wrench>
        </link>
        <link name='link_2'>
          <pose>4.0623 -1.69029 0.3 -2.07316 -0.292195 1.67072</pose>
          <velocity>0.002971 -0.001067 -0.00475 0.003113 0.010199 -0.000237</velocity>
          <acceleration>1.9971 -1.47354 -4.86218 -1.3073 -1.11098 1.16881</acceleration>
          <wrench>1.9971 -1.47354 -4.86218 0 -0 0</wrench>
        </link>
        <link name='link_3'>
          <pose>3.80409 -1.67573 0.159641 -2.07316 -0.292195 1.67072</pose>
          <velocity>0.001617 -0.000549 -0.002053 0.003124 0.010148 -0.000251</velocity>
          <acceleration>0.556088 -0.688397 -2.11615 -1.25017 -1.09994 1.46541</acceleration>
          <wrench>0.556088 -0.688397 -2.11615 0 -0 0</wrench>
        </link>
      </model>
      <model name='Robot_clone'>
        <pose>3.65195 0.169181 0.213456 3e-06 -1.2e-05 -1.56002</pose>
        <scale>1 1 1</scale>
        <link name='link_0'>
          <pose>3.59466 -0.017231 0.2 3e-06 -1.2e-05 -1.56002</pose>
          <velocity>-0.000558 -0.000289 -0.004717 -0.011845 -0.002914 -8.1e-05</velocity>
          <acceleration>0.001077 0.046352 -9.83849 -0.038386 -0.007641 -0.019099</acceleration>
          <wrench>0.001077 0.046352 -9.83849 0 -0 0</wrench>
        </link>
        <link name='link_1'>
          <pose>3.24143 0.27898 0.199996 1.5707 -0.332036 -1.55999</pose>
          <velocity>-0.000533 -0.000241 -0.009259 0.001641 -0.002778 -7.5e-05</velocity>
          <acceleration>0.016587 0.083009 -9.85817 0.000322 -0.029923 -0.0073</acceleration>
          <wrench>0.016587 0.083009 -9.85817 0 -0 0</wrench>
        </link>
        <link name='link_1_clone'>
          <pose>3.24789 -0.320985 0.200003 1.5707 0.021829 -1.56002</pose>
          <velocity>-0.000593 -0.000261 -0.002119 0.001605 -0.002706 -4.8e-05</velocity>
          <acceleration>-0.029707 0.055723 -9.80949 -0.001158 0.107779 0.031203</acceleration>
          <wrench>-0.029707 0.055723 -9.80949 0 -0 0</wrench>
        </link>
        <link name='link_1_clone_0'>
          <pose>3.94142 0.286524 0.199998 1.5707 -0.265153 -1.56</pose>
          <velocity>-0.000525 -0.000296 -0.007292 0.001892 -0.002749 -8e-06</velocity>
          <acceleration>0.02704 0.076281 -9.83012 -0.000136 0.013508 0.084769</acceleration>
          <wrench>0.02704 0.076281 -9.83012 0 -0 0</wrench>
        </link>
        <link name='link_1_clone_1'>
          <pose>3.94789 -0.313442 0.200005 1.5707 0.059121 -1.56003</pose>
          <velocity>-0.000572 -0.000319 -0.000156 0.001866 -0.00277 -3.2e-05</velocity>
          <acceleration>-0.013363 0.048063 -9.7887 -0.000213 0.020362 0.057198</acceleration>
          <wrench>-0.013363 0.048063 -9.7887 0 -0 0</wrench>
        </link>
        <link name='link_2'>
          <pose>3.57444 0.002554 0.3 -2.07324 -0.2926 0.146497</pose>
          <velocity>-0.000849 0.000869 -0.004989 -0.0032 -0.001729 -0.000715</velocity>
          <acceleration>0.000826 0.003879 -9.80487 0.177673 -0.001419 0.000745</acceleration>
          <wrench>0.000826 0.003879 -9.80487 0 -0 0</wrench>
        </link>
        <link name='link_3'>
          <pose>3.57703 0.261164 0.159637 -2.07324 -0.2926 0.146497</pose>
          <velocity>-0.000421 0.000209 -0.005758 -0.00334 -0.00173 -0.000717</velocity>
          <acceleration>-0.002461 -0.313307 -9.67017 -0.050521 0.00092 0.000585</acceleration>
          <wrench>-0.002461 -0.313307 -9.67017 0 -0 0</wrench>
        </link>
      </model>
      <model name='cafe_table'>
        <pose>0.655672 -0.222057 0 0 -0 0</pose>
        <scale>1 1 1</scale>
        <link name='link'>
          <pose>0.655672 -0.222057 0 0 -0 0</pose>
          <velocity>0 0 0 0 -0 0</velocity>
          <acceleration>0 0 0 0 -0 0</acceleration>
          <wrench>0 0 0 0 -0 0</wrench>
        </link>
      </model>
      <model name='ground_plane'>
        <pose>0 0 0 0 -0 0</pose>
        <scale>1 1 1</scale>
        <link name='link'>
          <pose>0 0 0 0 -0 0</pose>
          <velocity>0 0 0 0 -0 0</velocity>
          <acceleration>0 0 0 0 -0 0</acceleration>
          <wrench>0 0 0 0 -0 0</wrench>
        </link>
      </model>
      <model name='my_ball'>
        <pose>6 -3 0.1 0 -0 0</pose>
        <scale>1 1 1</scale>
        <link name='link_0'>
          <pose>6 -3 0.1 0 -0 0</pose>
          <velocity>0 0 0 0 -0 0</velocity>
          <acceleration>0 0 0 0 -0 0</acceleration>
          <wrench>0 0 0 0 -0 0</wrench>
        </link>
      </model>
      <light name='sun'>
        <pose>0 0 10 0 -0 0</pose>
      </light>
    </state>
    <gui fullscreen='0'>
      <camera name='user_camera'>
        <pose>6.47013 -2.79085 5.75054 0 1.43525 2.82829</pose>
        <view_controller>orbit</view_controller>
        <projection_type>perspective</projection_type>
      </camera>
    </gui>
    <model name='Robot'>
      <link name='link_0'>
        <inertial>
          <mass>1</mass>
          <inertia>
            <ixx>0.166667</ixx>
            <ixy>0</ixy>
            <ixz>0</ixz>
            <iyy>0.166667</iyy>
            <iyz>0</iyz>
            <izz>0.166667</izz>
          </inertia>
          <pose>0 0 0 0 -0 0</pose>
        </inertial>
        <pose>0.185783 -0.0593 -0.013458 0 -0 0</pose>
        <gravity>1</gravity>
        <self_collide>0</self_collide>
        <kinematic>0</kinematic>
        <enable_wind>0</enable_wind>
        <visual name='visual'>
          <pose>0 0 0 0 -0 0</pose>
          <geometry>
            <box>
              <size>1 0.6 0.2</size>
            </box>
          </geometry>
          <material>
            <lighting>1</lighting>
            <script>
              <uri>file://media/materials/scripts/gazebo.material</uri>
              <name>Gazebo/Grey</name>
            </script>
            <shader type='pixel'>
              <normal_map>__default__</normal_map>
            </shader>
            <ambient>0.3 0.3 0.3 1</ambient>
            <diffuse>0.7 0.7 0.7 1</diffuse>
            <specular>0.01 0.01 0.01 1</specular>
            <emissive>0 0 0 1</emissive>
          </material>
          <transparency>0</transparency>
          <cast_shadows>1</cast_shadows>
        </visual>
        <collision name='collision'>
          <laser_retro>0</laser_retro>
          <max_contacts>10</max_contacts>
          <pose>0 0 0 0 -0 0</pose>
          <geometry>
            <box>
              <size>1 0.6 0.2</size>
            </box>
          </geometry>
          <surface>
            <friction>
              <ode>
                <mu>1</mu>
                <mu2>1</mu2>
                <fdir1>0 0 0</fdir1>
                <slip1>0</slip1>
                <slip2>0</slip2>
              </ode>
              <torsional>
                <coefficient>1</coefficient>
                <patch_radius>0</patch_radius>
                <surface_radius>0</surface_radius>
                <use_patch_radius>1</use_patch_radius>
                <ode>
                  <slip>0</slip>
                </ode>
              </torsional>
            </friction>
            <bounce>
              <restitution_coefficient>0</restitution_coefficient>
              <threshold>1e+06</threshold>
            </bounce>
            <contact>
              <collide_without_contact>0</collide_without_contact>
              <collide_without_contact_bitmask>1</collide_without_contact_bitmask>
              <collide_bitmask>1</collide_bitmask>
              <ode>
                <soft_cfm>0</soft_cfm>
                <soft_erp>0.2</soft_erp>
                <kp>1e+13</kp>
                <kd>1</kd>
                <max_vel>0.01</max_vel>
                <min_depth>0</min_depth>
              </ode>
              <bullet>
                <split_impulse>1</split_impulse>
                <split_impulse_penetration_threshold>-0.01</split_impulse_penetration_threshold>
                <soft_cfm>0</soft_cfm>
                <soft_erp>0.2</soft_erp>
                <kp>1e+13</kp>
                <kd>1</kd>
              </bullet>
            </contact>
          </surface>
        </collision>
      </link>
      <link name='link_1'>
        <inertial>
          <mass>1</mass>
          <inertia>
            <ixx>0.145833</ixx>
            <ixy>0</ixy>
            <ixz>0</ixz>
            <iyy>0.145833</iyy>
            <iyz>0</iyz>
            <izz>0.125</izz>
          </inertia>
          <pose>0 0 0 0 -0 0</pose>
        </inertial>
        <pose>-0.114217 -0.40932 -0.013458 1.5707 -0 0</pose>
        <gravity>1</gravity>
        <self_collide>0</self_collide>
        <kinematic>0</kinematic>
        <enable_wind>0</enable_wind>
        <visual name='visual'>
          <pose>0 0 0 0 -0 0</pose>
          <geometry>
            <cylinder>
              <radius>0.2</radius>
              <length>0.1</length>
            </cylinder>
          </geometry>
          <material>
            <lighting>1</lighting>
            <script>
              <uri>file://media/materials/scripts/gazebo.material</uri>
              <name>Gazebo/Grey</name>
            </script>
            <shader type='pixel'>
              <normal_map>__default__</normal_map>
            </shader>
            <ambient>0.3 0.3 0.3 1</ambient>
            <diffuse>0.7 0.7 0.7 1</diffuse>
            <specular>0.01 0.01 0.01 1</specular>
            <emissive>0 0 0 1</emissive>
          </material>
          <transparency>0</transparency>
          <cast_shadows>1</cast_shadows>
        </visual>
        <collision name='collision'>
          <laser_retro>0</laser_retro>
          <max_contacts>10</max_contacts>
          <pose>0 0 0 0 -0 0</pose>
          <geometry>
            <cylinder>
              <radius>0.2</radius>
              <length>0.1</length>
            </cylinder>
          </geometry>
          <surface>
            <friction>
              <ode>
                <mu>1</mu>
                <mu2>1</mu2>
                <fdir1>0 0 0</fdir1>
                <slip1>0</slip1>
                <slip2>0</slip2>
              </ode>
              <torsional>
                <coefficient>1</coefficient>
                <patch_radius>0</patch_radius>
                <surface_radius>0</surface_radius>
                <use_patch_radius>1</use_patch_radius>
                <ode>
                  <slip>0</slip>
                </ode>
              </torsional>
            </friction>
            <bounce>
              <restitution_coefficient>0</restitution_coefficient>
              <threshold>1e+06</threshold>
            </bounce>
            <contact>
              <collide_without_contact>0</collide_without_contact>
              <collide_without_contact_bitmask>1</collide_without_contact_bitmask>
              <collide_bitmask>1</collide_bitmask>
              <ode>
                <soft_cfm>0</soft_cfm>
                <soft_erp>0.2</soft_erp>
                <kp>1e+13</kp>
                <kd>1</kd>
                <max_vel>0.01</max_vel>
                <min_depth>0</min_depth>
              </ode>
              <bullet>
                <split_impulse>1</split_impulse>
                <split_impulse_penetration_threshold>-0.01</split_impulse_penetration_threshold>
                <soft_cfm>0</soft_cfm>
                <soft_erp>0.2</soft_erp>
                <kp>1e+13</kp>
                <kd>1</kd>
              </bullet>
            </contact>
          </surface>
        </collision>
      </link>
      <link name='link_1_clone'>
        <inertial>
          <mass>1</mass>
          <inertia>
            <ixx>0.145833</ixx>
            <ixy>0</ixy>
            <ixz>0</ixz>
            <iyy>0.145833</iyy>
            <iyz>0</iyz>
            <izz>0.125</izz>
          </inertia>
          <pose>0 0 0 0 -0 0</pose>
        </inertial>
        <pose>0.485783 -0.40932 -0.013458 1.5707 -0 0</pose>
        <gravity>1</gravity>
        <self_collide>0</self_collide>
        <kinematic>0</kinematic>
        <enable_wind>0</enable_wind>
        <visual name='visual'>
          <pose>0 0 0 0 -0 0</pose>
          <geometry>
            <cylinder>
              <radius>0.2</radius>
              <length>0.1</length>
            </cylinder>
          </geometry>
          <material>
            <lighting>1</lighting>
            <script>
              <uri>file://media/materials/scripts/gazebo.material</uri>
              <name>Gazebo/Grey</name>
            </script>
            <shader type='pixel'>
              <normal_map>__default__</normal_map>
            </shader>
            <ambient>0.3 0.3 0.3 1</ambient>
            <diffuse>0.7 0.7 0.7 1</diffuse>
            <specular>0.01 0.01 0.01 1</specular>
            <emissive>0 0 0 1</emissive>
          </material>
          <transparency>0</transparency>
          <cast_shadows>1</cast_shadows>
        </visual>
        <collision name='collision'>
          <laser_retro>0</laser_retro>
          <max_contacts>10</max_contacts>
          <pose>0 0 0 0 -0 0</pose>
          <geometry>
            <cylinder>
              <radius>0.2</radius>
              <length>0.1</length>
            </cylinder>
          </geometry>
          <surface>
            <friction>
              <ode>
                <mu>1</mu>
                <mu2>1</mu2>
                <fdir1>0 0 0</fdir1>
                <slip1>0</slip1>
                <slip2>0</slip2>
              </ode>
              <torsional>
                <coefficient>1</coefficient>
                <patch_radius>0</patch_radius>
                <surface_radius>0</surface_radius>
                <use_patch_radius>1</use_patch_radius>
                <ode>
                  <slip>0</slip>
                </ode>
              </torsional>
            </friction>
            <bounce>
              <restitution_coefficient>0</restitution_coefficient>
              <threshold>1e+06</threshold>
            </bounce>
            <contact>
              <collide_without_contact>0</collide_without_contact>
              <collide_without_contact_bitmask>1</collide_without_contact_bitmask>
              <collide_bitmask>1</collide_bitmask>
              <ode>
                <soft_cfm>0</soft_cfm>
                <soft_erp>0.2</soft_erp>
                <kp>1e+13</kp>
                <kd>1</kd>
                <max_vel>0.01</max_vel>
                <min_depth>0</min_depth>
              </ode>
              <bullet>
                <split_impulse>1</split_impulse>
                <split_impulse_penetration_threshold>-0.01</split_impulse_penetration_threshold>
                <soft_cfm>0</soft_cfm>
                <soft_erp>0.2</soft_erp>
                <kp>1e+13</kp>
                <kd>1</kd>
              </bullet>
            </contact>
          </surface>
        </collision>
      </link>
      <link name='link_1_clone_0'>
        <inertial>
          <mass>1</mass>
          <inertia>
            <ixx>0.145833</ixx>
            <ixy>0</ixy>
            <ixz>0</ixz>
            <iyy>0.145833</iyy>
            <iyz>0</iyz>
            <izz>0.125</izz>
          </inertia>
          <pose>0 0 0 0 -0 0</pose>
        </inertial>
        <pose>-0.114217 0.290719 -0.013458 1.5707 -0 0</pose>
        <gravity>1</gravity>
        <self_collide>0</self_collide>
        <kinematic>0</kinematic>
        <enable_wind>0</enable_wind>
        <visual name='visual'>
          <pose>0 0 0 0 -0 0</pose>
          <geometry>
            <cylinder>
              <radius>0.2</radius>
              <length>0.1</length>
            </cylinder>
          </geometry>
          <material>
            <lighting>1</lighting>
            <script>
              <uri>file://media/materials/scripts/gazebo.material</uri>
              <name>Gazebo/Grey</name>
            </script>
            <shader type='pixel'>
              <normal_map>__default__</normal_map>
            </shader>
            <ambient>0.3 0.3 0.3 1</ambient>
            <diffuse>0.7 0.7 0.7 1</diffuse>
            <specular>0.01 0.01 0.01 1</specular>
            <emissive>0 0 0 1</emissive>
          </material>
          <transparency>0</transparency>
          <cast_shadows>1</cast_shadows>
        </visual>
        <collision name='collision'>
          <laser_retro>0</laser_retro>
          <max_contacts>10</max_contacts>
          <pose>0 0 0 0 -0 0</pose>
          <geometry>
            <cylinder>
              <radius>0.2</radius>
              <length>0.1</length>
            </cylinder>
          </geometry>
          <surface>
            <friction>
              <ode>
                <mu>1</mu>
                <mu2>1</mu2>
                <fdir1>0 0 0</fdir1>
                <slip1>0</slip1>
                <slip2>0</slip2>
              </ode>
              <torsional>
                <coefficient>1</coefficient>
                <patch_radius>0</patch_radius>
                <surface_radius>0</surface_radius>
                <use_patch_radius>1</use_patch_radius>
                <ode>
                  <slip>0</slip>
                </ode>
              </torsional>
            </friction>
            <bounce>
              <restitution_coefficient>0</restitution_coefficient>
              <threshold>1e+06</threshold>
            </bounce>
            <contact>
              <collide_without_contact>0</collide_without_contact>
              <collide_without_contact_bitmask>1</collide_without_contact_bitmask>
              <collide_bitmask>1</collide_bitmask>
              <ode>
                <soft_cfm>0</soft_cfm>
                <soft_erp>0.2</soft_erp>
                <kp>1e+13</kp>
                <kd>1</kd>
                <max_vel>0.01</max_vel>
                <min_depth>0</min_depth>
              </ode>
              <bullet>
                <split_impulse>1</split_impulse>
                <split_impulse_penetration_threshold>-0.01</split_impulse_penetration_threshold>
                <soft_cfm>0</soft_cfm>
                <soft_erp>0.2</soft_erp>
                <kp>1e+13</kp>
                <kd>1</kd>
              </bullet>
            </contact>
          </surface>
        </collision>
      </link>
      <link name='link_1_clone_1'>
        <inertial>
          <mass>1</mass>
          <inertia>
            <ixx>0.145833</ixx>
            <ixy>0</ixy>
            <ixz>0</ixz>
            <iyy>0.145833</iyy>
            <iyz>0</iyz>
            <izz>0.125</izz>
          </inertia>
          <pose>0 0 0 0 -0 0</pose>
        </inertial>
        <pose>0.485783 0.290719 -0.013458 1.5707 -0 0</pose>
        <gravity>1</gravity>
        <self_collide>0</self_collide>
        <kinematic>0</kinematic>
        <enable_wind>0</enable_wind>
        <visual name='visual'>
          <pose>0 0 0 0 -0 0</pose>
          <geometry>
            <cylinder>
              <radius>0.2</radius>
              <length>0.1</length>
            </cylinder>
          </geometry>
          <material>
            <lighting>1</lighting>
            <script>
              <uri>file://media/materials/scripts/gazebo.material</uri>
              <name>Gazebo/Grey</name>
            </script>
            <shader type='pixel'>
              <normal_map>__default__</normal_map>
            </shader>
            <ambient>0.3 0.3 0.3 1</ambient>
            <diffuse>0.7 0.7 0.7 1</diffuse>
            <specular>0.01 0.01 0.01 1</specular>
            <emissive>0 0 0 1</emissive>
          </material>
          <transparency>0</transparency>
          <cast_shadows>1</cast_shadows>
        </visual>
        <collision name='collision'>
          <laser_retro>0</laser_retro>
          <max_contacts>10</max_contacts>
          <pose>0 0 0 0 -0 0</pose>
          <geometry>
            <cylinder>
              <radius>0.2</radius>
              <length>0.1</length>
            </cylinder>
          </geometry>
          <surface>
            <friction>
              <ode>
                <mu>1</mu>
                <mu2>1</mu2>
                <fdir1>0 0 0</fdir1>
                <slip1>0</slip1>
                <slip2>0</slip2>
              </ode>
              <torsional>
                <coefficient>1</coefficient>
                <patch_radius>0</patch_radius>
                <surface_radius>0</surface_radius>
                <use_patch_radius>1</use_patch_radius>
                <ode>
                  <slip>0</slip>
                </ode>
              </torsional>
            </friction>
            <bounce>
              <restitution_coefficient>0</restitution_coefficient>
              <threshold>1e+06</threshold>
            </bounce>
            <contact>
              <collide_without_contact>0</collide_without_contact>
              <collide_without_contact_bitmask>1</collide_without_contact_bitmask>
              <collide_bitmask>1</collide_bitmask>
              <ode>
                <soft_cfm>0</soft_cfm>
                <soft_erp>0.2</soft_erp>
                <kp>1e+13</kp>
                <kd>1</kd>
                <max_vel>0.01</max_vel>
                <min_depth>0</min_depth>
              </ode>
              <bullet>
                <split_impulse>1</split_impulse>
                <split_impulse_penetration_threshold>-0.01</split_impulse_penetration_threshold>
                <soft_cfm>0</soft_cfm>
                <soft_erp>0.2</soft_erp>
                <kp>1e+13</kp>
                <kd>1</kd>
              </bullet>
            </contact>
          </surface>
        </collision>
      </link>
      <link name='link_2'>
        <inertial>
          <mass>1</mass>
          <inertia>
            <ixx>0.1</ixx>
            <ixy>0</ixy>
            <ixz>0</ixz>
            <iyy>0.1</iyy>
            <iyz>0</iyz>
            <izz>0.1</izz>
          </inertia>
          <pose>0 0 0 0 -0 0</pose>
        </inertial>
        <pose>0.165783 -0.0793 0.086542 0 -0 0</pose>
        <gravity>1</gravity>
        <self_collide>0</self_collide>
        <kinematic>0</kinematic>
        <enable_wind>0</enable_wind>
        <visual name='visual'>
          <pose>0 0 0 0 -0 0</pose>
          <geometry>
            <sphere>
              <radius>0.1</radius>
            </sphere>
          </geometry>
          <material>
            <lighting>1</lighting>
            <script>
              <uri>file://media/materials/scripts/gazebo.material</uri>
              <name>Gazebo/Grey</name>
            </script>
            <shader type='pixel'>
              <normal_map>__default__</normal_map>
            </shader>
            <ambient>0.3 0.3 0.3 1</ambient>
            <diffuse>0.7 0.7 0.7 1</diffuse>
            <specular>0.01 0.01 0.01 1</specular>
            <emissive>0 0 0 1</emissive>
          </material>
          <transparency>0</transparency>
          <cast_shadows>1</cast_shadows>
        </visual>
        <collision name='collision'>
          <laser_retro>0</laser_retro>
          <max_contacts>10</max_contacts>
          <pose>0 0 0 0 -0 0</pose>
          <geometry>
            <sphere>
              <radius>0.1</radius>
            </sphere>
          </geometry>
          <surface>
            <friction>
              <ode>
                <mu>1</mu>
                <mu2>1</mu2>
                <fdir1>0 0 0</fdir1>
                <slip1>0</slip1>
                <slip2>0</slip2>
              </ode>
              <torsional>
                <coefficient>1</coefficient>
                <patch_radius>0</patch_radius>
                <surface_radius>0</surface_radius>
                <use_patch_radius>1</use_patch_radius>
                <ode>
                  <slip>0</slip>
                </ode>
              </torsional>
            </friction>
            <bounce>
              <restitution_coefficient>0</restitution_coefficient>
              <threshold>1e+06</threshold>
            </bounce>
            <contact>
              <collide_without_contact>0</collide_without_contact>
              <collide_without_contact_bitmask>1</collide_without_contact_bitmask>
              <collide_bitmask>1</collide_bitmask>
              <ode>
                <soft_cfm>0</soft_cfm>
                <soft_erp>0.2</soft_erp>
                <kp>1e+13</kp>
                <kd>1</kd>
                <max_vel>0.01</max_vel>
                <min_depth>0</min_depth>
              </ode>
              <bullet>
                <split_impulse>1</split_impulse>
                <split_impulse_penetration_threshold>-0.01</split_impulse_penetration_threshold>
                <soft_cfm>0</soft_cfm>
                <soft_erp>0.2</soft_erp>
                <kp>1e+13</kp>
                <kd>1</kd>
              </bullet>
            </contact>
          </surface>
        </collision>
      </link>
      <link name='link_3'>
        <inertial>
          <mass>1</mass>
          <inertia>
            <ixx>0.145833</ixx>
            <ixy>0</ixy>
            <ixz>0</ixz>
            <iyy>0.145833</iyy>
            <iyz>0</iyz>
            <izz>0.125</izz>
          </inertia>
          <pose>0 0 0 0 -0 0</pose>
        </inertial>
        <pose>0.163895 -0.074346 0.380751 0 -0 0</pose>
        <gravity>1</gravity>
        <self_collide>0</self_collide>
        <kinematic>0</kinematic>
        <enable_wind>0</enable_wind>
        <visual name='visual'>
          <pose>0 0 0 0 -0 0</pose>
          <geometry>
            <cylinder>
              <radius>0.05</radius>
              <length>0.5</length>
            </cylinder>
          </geometry>
          <material>
            <lighting>1</lighting>
            <script>
              <uri>file://media/materials/scripts/gazebo.material</uri>
              <name>Gazebo/Grey</name>
            </script>
            <shader type='pixel'>
              <normal_map>__default__</normal_map>
            </shader>
            <ambient>0.3 0.3 0.3 1</ambient>
            <diffuse>0.7 0.7 0.7 1</diffuse>
            <specular>0.01 0.01 0.01 1</specular>
            <emissive>0 0 0 1</emissive>
          </material>
          <transparency>0</transparency>
          <cast_shadows>1</cast_shadows>
        </visual>
        <collision name='collision'>
          <laser_retro>0</laser_retro>
          <max_contacts>10</max_contacts>
          <pose>0 0 0 0 -0 0</pose>
          <geometry>
            <cylinder>
              <radius>0.05</radius>
              <length>0.5</length>
            </cylinder>
          </geometry>
          <surface>
            <friction>
              <ode>
                <mu>1</mu>
                <mu2>1</mu2>
                <fdir1>0 0 0</fdir1>
                <slip1>0</slip1>
                <slip2>0</slip2>
              </ode>
              <torsional>
                <coefficient>1</coefficient>
                <patch_radius>0</patch_radius>
                <surface_radius>0</surface_radius>
                <use_patch_radius>1</use_patch_radius>
                <ode>
                  <slip>0</slip>
                </ode>
              </torsional>
            </friction>
            <bounce>
              <restitution_coefficient>0</restitution_coefficient>
              <threshold>1e+06</threshold>
            </bounce>
            <contact>
              <collide_without_contact>0</collide_without_contact>
              <collide_without_contact_bitmask>1</collide_without_contact_bitmask>
              <collide_bitmask>1</collide_bitmask>
              <ode>
                <soft_cfm>0</soft_cfm>
                <soft_erp>0.2</soft_erp>
                <kp>1e+13</kp>
                <kd>1</kd>
                <max_vel>0.01</max_vel>
                <min_depth>0</min_depth>
              </ode>
              <bullet>
                <split_impulse>1</split_impulse>
                <split_impulse_penetration_threshold>-0.01</split_impulse_penetration_threshold>
                <soft_cfm>0</soft_cfm>
                <soft_erp>0.2</soft_erp>
                <kp>1e+13</kp>
                <kd>1</kd>
              </bullet>
            </contact>
          </surface>
        </collision>
      </link>
      <joint name='link_0_JOINT_0' type='revolute'>
        <parent>link_0</parent>
        <child>link_1</child>
        <pose>0 0 0 0 -0 0</pose>
        <axis>
          <xyz>0 0 1</xyz>
          <limit>
            <lower>-1.79769e+308</lower>
            <upper>1.79769e+308</upper>
            <effort>-1</effort>
            <velocity>-1</velocity>
          </limit>
          <dynamics>
            <spring_reference>0</spring_reference>
            <spring_stiffness>0</spring_stiffness>
            <damping>0</damping>
          </dynamics>
        </axis>
        <physics>
          <ode>
            <limit>
              <cfm>0</cfm>
              <erp>0.2</erp>
            </limit>
            <suspension>
              <cfm>0</cfm>
              <erp>0.2</erp>
            </suspension>
          </ode>
        </physics>
      </joint>
      <joint name='link_0_JOINT_1' type='revolute'>
        <parent>link_0</parent>
        <child>link_1_clone</child>
        <pose>0 0 0 0 -0 0</pose>
        <axis>
          <xyz>0 0 1</xyz>
          <limit>
            <lower>-1.79769e+308</lower>
            <upper>1.79769e+308</upper>
            <effort>-1</effort>
            <velocity>-1</velocity>
          </limit>
          <dynamics>
            <spring_reference>0</spring_reference>
            <spring_stiffness>0</spring_stiffness>
            <damping>0</damping>
          </dynamics>
        </axis>
        <physics>
          <ode>
            <limit>
              <cfm>0</cfm>
              <erp>0.2</erp>
            </limit>
            <suspension>
              <cfm>0</cfm>
              <erp>0.2</erp>
            </suspension>
          </ode>
        </physics>
      </joint>
      <joint name='link_0_JOINT_2' type='revolute'>
        <parent>link_0</parent>
        <child>link_1_clone_0</child>
        <pose>0 0 0 0 -0 0</pose>
        <axis>
          <xyz>0 0 1</xyz>
          <limit>
            <lower>-1.79769e+308</lower>
            <upper>1.79769e+308</upper>
            <effort>-1</effort>
            <velocity>-1</velocity>
          </limit>
          <dynamics>
            <spring_reference>0</spring_reference>
            <spring_stiffness>0</spring_stiffness>
            <damping>0</damping>
          </dynamics>
        </axis>
        <physics>
          <ode>
            <limit>
              <cfm>0</cfm>
              <erp>0.2</erp>
            </limit>
            <suspension>
              <cfm>0</cfm>
              <erp>0.2</erp>
            </suspension>
          </ode>
        </physics>
      </joint>
      <joint name='link_0_JOINT_3' type='revolute'>
        <parent>link_0</parent>
        <child>link_1_clone_1</child>
        <pose>0 0 0 0 -0 0</pose>
        <axis>
          <xyz>0 0 1</xyz>
          <limit>
            <lower>-1.79769e+308</lower>
            <upper>1.79769e+308</upper>
            <effort>-1</effort>
            <velocity>-1</velocity>
          </limit>
          <dynamics>
            <spring_reference>0</spring_reference>
            <spring_stiffness>0</spring_stiffness>
            <damping>0</damping>
          </dynamics>
        </axis>
        <physics>
          <ode>
            <limit>
              <cfm>0</cfm>
              <erp>0.2</erp>
            </limit>
            <suspension>
              <cfm>0</cfm>
              <erp>0.2</erp>
            </suspension>
          </ode>
        </physics>
      </joint>
      <joint name='link_0_JOINT_5' type='ball'>
        <parent>link_0</parent>
        <child>link_2</child>
        <pose>0 0 0 0 -0 0</pose>
        <physics>
          <ode>
            <limit>
              <cfm>0</cfm>
              <erp>0.2</erp>
            </limit>
            <suspension>
              <cfm>0</cfm>
              <erp>0.2</erp>
            </suspension>
          </ode>
        </physics>
      </joint>
      <joint name='link_2_JOINT_7' type='fixed'>
        <parent>link_2</parent>
        <child>link_3</child>
        <pose>0 0 0 0 -0 0</pose>
        <physics>
          <ode>
            <limit>
              <cfm>0</cfm>
              <erp>0.2</erp>
            </limit>
            <suspension>
              <cfm>0</cfm>
              <erp>0.2</erp>
            </suspension>
          </ode>
        </physics>
      </joint>
      <static>0</static>
      <allow_auto_disable>1</allow_auto_disable>
      <pose>0.910587 -7.3263 0.213458 0 -0 0</pose>
    </model>
    <model name='Robot_clone'>
      <link name='link_0'>
        <inertial>
          <mass>1</mass>
          <inertia>
            <ixx>0.166667</ixx>
            <ixy>0</ixy>
            <ixz>0</ixz>
            <iyy>0.166667</iyy>
            <iyz>0</iyz>
            <izz>0.166667</izz>
          </inertia>
          <pose>0 0 0 0 -0 0</pose>
        </inertial>
        <pose>0.185783 -0.0593 -0.013458 0 -0 0</pose>
        <gravity>1</gravity>
        <self_collide>0</self_collide>
        <kinematic>0</kinematic>
        <enable_wind>0</enable_wind>
        <visual name='visual'>
          <pose>0 0 0 0 -0 0</pose>
          <geometry>
            <box>
              <size>1 0.6 0.2</size>
            </box>
          </geometry>
          <material>
            <lighting>1</lighting>
            <script>
              <uri>file://media/materials/scripts/gazebo.material</uri>
              <name>Gazebo/Grey</name>
            </script>
            <shader type='pixel'>
              <normal_map>__default__</normal_map>
            </shader>
            <ambient>0.3 0.3 0.3 1</ambient>
            <diffuse>0.7 0.7 0.7 1</diffuse>
            <specular>0.01 0.01 0.01 1</specular>
            <emissive>0 0 0 1</emissive>
          </material>
          <transparency>0</transparency>
          <cast_shadows>1</cast_shadows>
        </visual>
        <collision name='collision'>
          <laser_retro>0</laser_retro>
          <max_contacts>10</max_contacts>
          <pose>0 0 0 0 -0 0</pose>
          <geometry>
            <box>
              <size>1 0.6 0.2</size>
            </box>
          </geometry>
          <surface>
            <friction>
              <ode>
                <mu>1</mu>
                <mu2>1</mu2>
                <fdir1>0 0 0</fdir1>
                <slip1>0</slip1>
                <slip2>0</slip2>
              </ode>
              <torsional>
                <coefficient>1</coefficient>
                <patch_radius>0</patch_radius>
                <surface_radius>0</surface_radius>
                <use_patch_radius>1</use_patch_radius>
                <ode>
                  <slip>0</slip>
                </ode>
              </torsional>
            </friction>
            <bounce>
              <restitution_coefficient>0</restitution_coefficient>
              <threshold>1e+06</threshold>
            </bounce>
            <contact>
              <collide_without_contact>0</collide_without_contact>
              <collide_without_contact_bitmask>1</collide_without_contact_bitmask>
              <collide_bitmask>1</collide_bitmask>
              <ode>
                <soft_cfm>0</soft_cfm>
                <soft_erp>0.2</soft_erp>
                <kp>1e+13</kp>
                <kd>1</kd>
                <max_vel>0.01</max_vel>
                <min_depth>0</min_depth>
              </ode>
              <bullet>
                <split_impulse>1</split_impulse>
                <split_impulse_penetration_threshold>-0.01</split_impulse_penetration_threshold>
                <soft_cfm>0</soft_cfm>
                <soft_erp>0.2</soft_erp>
                <kp>1e+13</kp>
                <kd>1</kd>
              </bullet>
            </contact>
          </surface>
        </collision>
      </link>
      <link name='link_1'>
        <inertial>
          <mass>1</mass>
          <inertia>
            <ixx>0.145833</ixx>
            <ixy>0</ixy>
            <ixz>0</ixz>
            <iyy>0.145833</iyy>
            <iyz>0</iyz>
            <izz>0.125</izz>
          </inertia>
          <pose>0 0 0 0 -0 0</pose>
        </inertial>
        <pose>-0.114217 -0.40932 -0.013458 1.5707 -0 0</pose>
        <gravity>1</gravity>
        <self_collide>0</self_collide>
        <kinematic>0</kinematic>
        <enable_wind>0</enable_wind>
        <visual name='visual'>
          <pose>0 0 0 0 -0 0</pose>
          <geometry>
            <cylinder>
              <radius>0.2</radius>
              <length>0.1</length>
            </cylinder>
          </geometry>
          <material>
            <lighting>1</lighting>
            <script>
              <uri>file://media/materials/scripts/gazebo.material</uri>
              <name>Gazebo/Grey</name>
            </script>
            <shader type='pixel'>
              <normal_map>__default__</normal_map>
            </shader>
            <ambient>0.3 0.3 0.3 1</ambient>
            <diffuse>0.7 0.7 0.7 1</diffuse>
            <specular>0.01 0.01 0.01 1</specular>
            <emissive>0 0 0 1</emissive>
          </material>
          <transparency>0</transparency>
          <cast_shadows>1</cast_shadows>
        </visual>
        <collision name='collision'>
          <laser_retro>0</laser_retro>
          <max_contacts>10</max_contacts>
          <pose>0 0 0 0 -0 0</pose>
          <geometry>
            <cylinder>
              <radius>0.2</radius>
              <length>0.1</length>
            </cylinder>
          </geometry>
          <surface>
            <friction>
              <ode>
                <mu>1</mu>
                <mu2>1</mu2>
                <fdir1>0 0 0</fdir1>
                <slip1>0</slip1>
                <slip2>0</slip2>
              </ode>
              <torsional>
                <coefficient>1</coefficient>
                <patch_radius>0</patch_radius>
                <surface_radius>0</surface_radius>
                <use_patch_radius>1</use_patch_radius>
                <ode>
                  <slip>0</slip>
                </ode>
              </torsional>
            </friction>
            <bounce>
              <restitution_coefficient>0</restitution_coefficient>
              <threshold>1e+06</threshold>
            </bounce>
            <contact>
              <collide_without_contact>0</collide_without_contact>
              <collide_without_contact_bitmask>1</collide_without_contact_bitmask>
              <collide_bitmask>1</collide_bitmask>
              <ode>
                <soft_cfm>0</soft_cfm>
                <soft_erp>0.2</soft_erp>
                <kp>1e+13</kp>
                <kd>1</kd>
                <max_vel>0.01</max_vel>
                <min_depth>0</min_depth>
              </ode>
              <bullet>
                <split_impulse>1</split_impulse>
                <split_impulse_penetration_threshold>-0.01</split_impulse_penetration_threshold>
                <soft_cfm>0</soft_cfm>
                <soft_erp>0.2</soft_erp>
                <kp>1e+13</kp>
                <kd>1</kd>
              </bullet>
            </contact>
          </surface>
        </collision>
      </link>
      <link name='link_1_clone'>
        <inertial>
          <mass>1</mass>
          <inertia>
            <ixx>0.145833</ixx>
            <ixy>0</ixy>
            <ixz>0</ixz>
            <iyy>0.145833</iyy>
            <iyz>0</iyz>
            <izz>0.125</izz>
          </inertia>
          <pose>0 0 0 0 -0 0</pose>
        </inertial>
        <pose>0.485783 -0.40932 -0.013458 1.5707 -0 0</pose>
        <gravity>1</gravity>
        <self_collide>0</self_collide>
        <kinematic>0</kinematic>
        <enable_wind>0</enable_wind>
        <visual name='visual'>
          <pose>0 0 0 0 -0 0</pose>
          <geometry>
            <cylinder>
              <radius>0.2</radius>
              <length>0.1</length>
            </cylinder>
          </geometry>
          <material>
            <lighting>1</lighting>
            <script>
              <uri>file://media/materials/scripts/gazebo.material</uri>
              <name>Gazebo/Grey</name>
            </script>
            <shader type='pixel'>
              <normal_map>__default__</normal_map>
            </shader>
            <ambient>0.3 0.3 0.3 1</ambient>
            <diffuse>0.7 0.7 0.7 1</diffuse>
            <specular>0.01 0.01 0.01 1</specular>
            <emissive>0 0 0 1</emissive>
          </material>
          <transparency>0</transparency>
          <cast_shadows>1</cast_shadows>
        </visual>
        <collision name='collision'>
          <laser_retro>0</laser_retro>
          <max_contacts>10</max_contacts>
          <pose>0 0 0 0 -0 0</pose>
          <geometry>
            <cylinder>
              <radius>0.2</radius>
              <length>0.1</length>
            </cylinder>
          </geometry>
          <surface>
            <friction>
              <ode>
                <mu>1</mu>
                <mu2>1</mu2>
                <fdir1>0 0 0</fdir1>
                <slip1>0</slip1>
                <slip2>0</slip2>
              </ode>
              <torsional>
                <coefficient>1</coefficient>
                <patch_radius>0</patch_radius>
                <surface_radius>0</surface_radius>
                <use_patch_radius>1</use_patch_radius>
                <ode>
                  <slip>0</slip>
                </ode>
              </torsional>
            </friction>
            <bounce>
              <restitution_coefficient>0</restitution_coefficient>
              <threshold>1e+06</threshold>
            </bounce>
            <contact>
              <collide_without_contact>0</collide_without_contact>
              <collide_without_contact_bitmask>1</collide_without_contact_bitmask>
              <collide_bitmask>1</collide_bitmask>
              <ode>
                <soft_cfm>0</soft_cfm>
                <soft_erp>0.2</soft_erp>
                <kp>1e+13</kp>
                <kd>1</kd>
                <max_vel>0.01</max_vel>
                <min_depth>0</min_depth>
              </ode>
              <bullet>
                <split_impulse>1</split_impulse>
                <split_impulse_penetration_threshold>-0.01</split_impulse_penetration_threshold>
                <soft_cfm>0</soft_cfm>
                <soft_erp>0.2</soft_erp>
                <kp>1e+13</kp>
                <kd>1</kd>
              </bullet>
            </contact>
          </surface>
        </collision>
      </link>
      <link name='link_1_clone_0'>
        <inertial>
          <mass>1</mass>
          <inertia>
            <ixx>0.145833</ixx>
            <ixy>0</ixy>
            <ixz>0</ixz>
            <iyy>0.145833</iyy>
            <iyz>0</iyz>
            <izz>0.125</izz>
          </inertia>
          <pose>0 0 0 0 -0 0</pose>
        </inertial>
        <pose>-0.114217 0.290719 -0.013458 1.5707 -0 0</pose>
        <gravity>1</gravity>
        <self_collide>0</self_collide>
        <kinematic>0</kinematic>
        <enable_wind>0</enable_wind>
        <visual name='visual'>
          <pose>0 0 0 0 -0 0</pose>
          <geometry>
            <cylinder>
              <radius>0.2</radius>
              <length>0.1</length>
            </cylinder>
          </geometry>
          <material>
            <lighting>1</lighting>
            <script>
              <uri>file://media/materials/scripts/gazebo.material</uri>
              <name>Gazebo/Grey</name>
            </script>
            <shader type='pixel'>
              <normal_map>__default__</normal_map>
            </shader>
            <ambient>0.3 0.3 0.3 1</ambient>
            <diffuse>0.7 0.7 0.7 1</diffuse>
            <specular>0.01 0.01 0.01 1</specular>
            <emissive>0 0 0 1</emissive>
          </material>
          <transparency>0</transparency>
          <cast_shadows>1</cast_shadows>
        </visual>
        <collision name='collision'>
          <laser_retro>0</laser_retro>
          <max_contacts>10</max_contacts>
          <pose>0 0 0 0 -0 0</pose>
          <geometry>
            <cylinder>
              <radius>0.2</radius>
              <length>0.1</length>
            </cylinder>
          </geometry>
          <surface>
            <friction>
              <ode>
                <mu>1</mu>
                <mu2>1</mu2>
                <fdir1>0 0 0</fdir1>
                <slip1>0</slip1>
                <slip2>0</slip2>
              </ode>
              <torsional>
                <coefficient>1</coefficient>
                <patch_radius>0</patch_radius>
                <surface_radius>0</surface_radius>
                <use_patch_radius>1</use_patch_radius>
                <ode>
                  <slip>0</slip>
                </ode>
              </torsional>
            </friction>
            <bounce>
              <restitution_coefficient>0</restitution_coefficient>
              <threshold>1e+06</threshold>
            </bounce>
            <contact>
              <collide_without_contact>0</collide_without_contact>
              <collide_without_contact_bitmask>1</collide_without_contact_bitmask>
              <collide_bitmask>1</collide_bitmask>
              <ode>
                <soft_cfm>0</soft_cfm>
                <soft_erp>0.2</soft_erp>
                <kp>1e+13</kp>
                <kd>1</kd>
                <max_vel>0.01</max_vel>
                <min_depth>0</min_depth>
              </ode>
              <bullet>
                <split_impulse>1</split_impulse>
                <split_impulse_penetration_threshold>-0.01</split_impulse_penetration_threshold>
                <soft_cfm>0</soft_cfm>
                <soft_erp>0.2</soft_erp>
                <kp>1e+13</kp>
                <kd>1</kd>
              </bullet>
            </contact>
          </surface>
        </collision>
      </link>
      <link name='link_1_clone_1'>
        <inertial>
          <mass>1</mass>
          <inertia>
            <ixx>0.145833</ixx>
            <ixy>0</ixy>
            <ixz>0</ixz>
            <iyy>0.145833</iyy>
            <iyz>0</iyz>
            <izz>0.125</izz>
          </inertia>
          <pose>0 0 0 0 -0 0</pose>
        </inertial>
        <pose>0.485783 0.290719 -0.013458 1.5707 -0 0</pose>
        <gravity>1</gravity>
        <self_collide>0</self_collide>
        <kinematic>0</kinematic>
        <enable_wind>0</enable_wind>
        <visual name='visual'>
          <pose>0 0 0 0 -0 0</pose>
          <geometry>
            <cylinder>
              <radius>0.2</radius>
              <length>0.1</length>
            </cylinder>
          </geometry>
          <material>
            <lighting>1</lighting>
            <script>
              <uri>file://media/materials/scripts/gazebo.material</uri>
              <name>Gazebo/Grey</name>
            </script>
            <shader type='pixel'>
              <normal_map>__default__</normal_map>
            </shader>
            <ambient>0.3 0.3 0.3 1</ambient>
            <diffuse>0.7 0.7 0.7 1</diffuse>
            <specular>0.01 0.01 0.01 1</specular>
            <emissive>0 0 0 1</emissive>
          </material>
          <transparency>0</transparency>
          <cast_shadows>1</cast_shadows>
        </visual>
        <collision name='collision'>
          <laser_retro>0</laser_retro>
          <max_contacts>10</max_contacts>
          <pose>0 0 0 0 -0 0</pose>
          <geometry>
            <cylinder>
              <radius>0.2</radius>
              <length>0.1</length>
            </cylinder>
          </geometry>
          <surface>
            <friction>
              <ode>
                <mu>1</mu>
                <mu2>1</mu2>
                <fdir1>0 0 0</fdir1>
                <slip1>0</slip1>
                <slip2>0</slip2>
              </ode>
              <torsional>
                <coefficient>1</coefficient>
                <patch_radius>0</patch_radius>
                <surface_radius>0</surface_radius>
                <use_patch_radius>1</use_patch_radius>
                <ode>
                  <slip>0</slip>
                </ode>
              </torsional>
            </friction>
            <bounce>
              <restitution_coefficient>0</restitution_coefficient>
              <threshold>1e+06</threshold>
            </bounce>
            <contact>
              <collide_without_contact>0</collide_without_contact>
              <collide_without_contact_bitmask>1</collide_without_contact_bitmask>
              <collide_bitmask>1</collide_bitmask>
              <ode>
                <soft_cfm>0</soft_cfm>
                <soft_erp>0.2</soft_erp>
                <kp>1e+13</kp>
                <kd>1</kd>
                <max_vel>0.01</max_vel>
                <min_depth>0</min_depth>
              </ode>
              <bullet>
                <split_impulse>1</split_impulse>
                <split_impulse_penetration_threshold>-0.01</split_impulse_penetration_threshold>
                <soft_cfm>0</soft_cfm>
                <soft_erp>0.2</soft_erp>
                <kp>1e+13</kp>
                <kd>1</kd>
              </bullet>
            </contact>
          </surface>
        </collision>
      </link>
      <link name='link_2'>
        <inertial>
          <mass>1</mass>
          <inertia>
            <ixx>0.1</ixx>
            <ixy>0</ixy>
            <ixz>0</ixz>
            <iyy>0.1</iyy>
            <iyz>0</iyz>
            <izz>0.1</izz>
          </inertia>
          <pose>0 0 0 0 -0 0</pose>
        </inertial>
        <pose>0.165783 -0.0793 0.086542 0 -0 0</pose>
        <gravity>1</gravity>
        <self_collide>0</self_collide>
        <kinematic>0</kinematic>
        <enable_wind>0</enable_wind>
        <visual name='visual'>
          <pose>0 0 0 0 -0 0</pose>
          <geometry>
            <sphere>
              <radius>0.1</radius>
            </sphere>
          </geometry>
          <material>
            <lighting>1</lighting>
            <script>
              <uri>file://media/materials/scripts/gazebo.material</uri>
              <name>Gazebo/Grey</name>
            </script>
            <shader type='pixel'>
              <normal_map>__default__</normal_map>
            </shader>
            <ambient>0.3 0.3 0.3 1</ambient>
            <diffuse>0.7 0.7 0.7 1</diffuse>
            <specular>0.01 0.01 0.01 1</specular>
            <emissive>0 0 0 1</emissive>
          </material>
          <transparency>0</transparency>
          <cast_shadows>1</cast_shadows>
        </visual>
        <collision name='collision'>
          <laser_retro>0</laser_retro>
          <max_contacts>10</max_contacts>
          <pose>0 0 0 0 -0 0</pose>
          <geometry>
            <sphere>
              <radius>0.1</radius>
            </sphere>
          </geometry>
          <surface>
            <friction>
              <ode>
                <mu>1</mu>
                <mu2>1</mu2>
                <fdir1>0 0 0</fdir1>
                <slip1>0</slip1>
                <slip2>0</slip2>
              </ode>
              <torsional>
                <coefficient>1</coefficient>
                <patch_radius>0</patch_radius>
                <surface_radius>0</surface_radius>
                <use_patch_radius>1</use_patch_radius>
                <ode>
                  <slip>0</slip>
                </ode>
              </torsional>
            </friction>
            <bounce>
              <restitution_coefficient>0</restitution_coefficient>
              <threshold>1e+06</threshold>
            </bounce>
            <contact>
              <collide_without_contact>0</collide_without_contact>
              <collide_without_contact_bitmask>1</collide_without_contact_bitmask>
              <collide_bitmask>1</collide_bitmask>
              <ode>
                <soft_cfm>0</soft_cfm>
                <soft_erp>0.2</soft_erp>
                <kp>1e+13</kp>
                <kd>1</kd>
                <max_vel>0.01</max_vel>
                <min_depth>0</min_depth>
              </ode>
              <bullet>
                <split_impulse>1</split_impulse>
                <split_impulse_penetration_threshold>-0.01</split_impulse_penetration_threshold>
                <soft_cfm>0</soft_cfm>
                <soft_erp>0.2</soft_erp>
                <kp>1e+13</kp>
                <kd>1</kd>
              </bullet>
            </contact>
          </surface>
        </collision>
      </link>
      <link name='link_3'>
        <inertial>
          <mass>1</mass>
          <inertia>
            <ixx>0.145833</ixx>
            <ixy>0</ixy>
            <ixz>0</ixz>
            <iyy>0.145833</iyy>
            <iyz>0</iyz>
            <izz>0.125</izz>
          </inertia>
          <pose>0 0 0 0 -0 0</pose>
        </inertial>
        <pose>0.163895 -0.074346 0.380751 0 -0 0</pose>
        <gravity>1</gravity>
        <self_collide>0</self_collide>
        <kinematic>0</kinematic>
        <enable_wind>0</enable_wind>
        <visual name='visual'>
          <pose>0 0 0 0 -0 0</pose>
          <geometry>
            <cylinder>
              <radius>0.05</radius>
              <length>0.5</length>
            </cylinder>
          </geometry>
          <material>
            <lighting>1</lighting>
            <script>
              <uri>file://media/materials/scripts/gazebo.material</uri>
              <name>Gazebo/Grey</name>
            </script>
            <shader type='pixel'>
              <normal_map>__default__</normal_map>
            </shader>
            <ambient>0.3 0.3 0.3 1</ambient>
            <diffuse>0.7 0.7 0.7 1</diffuse>
            <specular>0.01 0.01 0.01 1</specular>
            <emissive>0 0 0 1</emissive>
          </material>
          <transparency>0</transparency>
          <cast_shadows>1</cast_shadows>
        </visual>
        <collision name='collision'>
          <laser_retro>0</laser_retro>
          <max_contacts>10</max_contacts>
          <pose>0 0 0 0 -0 0</pose>
          <geometry>
            <cylinder>
              <radius>0.05</radius>
              <length>0.5</length>
            </cylinder>
          </geometry>
          <surface>
            <friction>
              <ode>
                <mu>1</mu>
                <mu2>1</mu2>
                <fdir1>0 0 0</fdir1>
                <slip1>0</slip1>
                <slip2>0</slip2>
              </ode>
              <torsional>
                <coefficient>1</coefficient>
                <patch_radius>0</patch_radius>
                <surface_radius>0</surface_radius>
                <use_patch_radius>1</use_patch_radius>
                <ode>
                  <slip>0</slip>
                </ode>
              </torsional>
            </friction>
            <bounce>
              <restitution_coefficient>0</restitution_coefficient>
              <threshold>1e+06</threshold>
            </bounce>
            <contact>
              <collide_without_contact>0</collide_without_contact>
              <collide_without_contact_bitmask>1</collide_without_contact_bitmask>
              <collide_bitmask>1</collide_bitmask>
              <ode>
                <soft_cfm>0</soft_cfm>
                <soft_erp>0.2</soft_erp>
                <kp>1e+13</kp>
                <kd>1</kd>
                <max_vel>0.01</max_vel>
                <min_depth>0</min_depth>
              </ode>
              <bullet>
                <split_impulse>1</split_impulse>
                <split_impulse_penetration_threshold>-0.01</split_impulse_penetration_threshold>
                <soft_cfm>0</soft_cfm>
                <soft_erp>0.2</soft_erp>
                <kp>1e+13</kp>
                <kd>1</kd>
              </bullet>
            </contact>
          </surface>
        </collision>
      </link>
      <joint name='link_0_JOINT_0' type='revolute'>
        <parent>link_0</parent>
        <child>link_1</child>
        <pose>0 0 0 0 -0 0</pose>
        <axis>
          <xyz>0 0 1</xyz>
          <limit>
            <lower>-1.79769e+308</lower>
            <upper>1.79769e+308</upper>
            <effort>-1</effort>
            <velocity>-1</velocity>
          </limit>
          <dynamics>
            <spring_reference>0</spring_reference>
            <spring_stiffness>0</spring_stiffness>
            <damping>0</damping>
          </dynamics>
        </axis>
        <physics>
          <ode>
            <limit>
              <cfm>0</cfm>
              <erp>0.2</erp>
            </limit>
            <suspension>
              <cfm>0</cfm>
              <erp>0.2</erp>
            </suspension>
          </ode>
        </physics>
      </joint>
      <joint name='link_0_JOINT_1' type='revolute'>
        <parent>link_0</parent>
        <child>link_1_clone</child>
        <pose>0 0 0 0 -0 0</pose>
        <axis>
          <xyz>0 0 1</xyz>
          <limit>
            <lower>-1.79769e+308</lower>
            <upper>1.79769e+308</upper>
            <effort>-1</effort>
            <velocity>-1</velocity>
          </limit>
          <dynamics>
            <spring_reference>0</spring_reference>
            <spring_stiffness>0</spring_stiffness>
            <damping>0</damping>
          </dynamics>
        </axis>
        <physics>
          <ode>
            <limit>
              <cfm>0</cfm>
              <erp>0.2</erp>
            </limit>
            <suspension>
              <cfm>0</cfm>
              <erp>0.2</erp>
            </suspension>
          </ode>
        </physics>
      </joint>
      <joint name='link_0_JOINT_2' type='revolute'>
        <parent>link_0</parent>
        <child>link_1_clone_0</child>
        <pose>0 0 0 0 -0 0</pose>
        <axis>
          <xyz>0 0 1</xyz>
          <limit>
            <lower>-1.79769e+308</lower>
            <upper>1.79769e+308</upper>
            <effort>-1</effort>
            <velocity>-1</velocity>
          </limit>
          <dynamics>
            <spring_reference>0</spring_reference>
            <spring_stiffness>0</spring_stiffness>
            <damping>0</damping>
          </dynamics>
        </axis>
        <physics>
          <ode>
            <limit>
              <cfm>0</cfm>
              <erp>0.2</erp>
            </limit>
            <suspension>
              <cfm>0</cfm>
              <erp>0.2</erp>
            </suspension>
          </ode>
        </physics>
      </joint>
      <joint name='link_0_JOINT_3' type='revolute'>
        <parent>link_0</parent>
        <child>link_1_clone_1</child>
        <pose>0 0 0 0 -0 0</pose>
        <axis>
          <xyz>0 0 1</xyz>
          <limit>
            <lower>-1.79769e+308</lower>
            <upper>1.79769e+308</upper>
            <effort>-1</effort>
            <velocity>-1</velocity>
          </limit>
          <dynamics>
            <spring_reference>0</spring_reference>
            <spring_stiffness>0</spring_stiffness>
            <damping>0</damping>
          </dynamics>
        </axis>
        <physics>
          <ode>
            <limit>
              <cfm>0</cfm>
              <erp>0.2</erp>
            </limit>
            <suspension>
              <cfm>0</cfm>
              <erp>0.2</erp>
            </suspension>
          </ode>
        </physics>
      </joint>
      <joint name='link_0_JOINT_5' type='ball'>
        <parent>link_0</parent>
        <child>link_2</child>
        <pose>0 0 0 0 -0 0</pose>
        <physics>
          <ode>
            <limit>
              <cfm>0</cfm>
              <erp>0.2</erp>
            </limit>
            <suspension>
              <cfm>0</cfm>
              <erp>0.2</erp>
            </suspension>
          </ode>
        </physics>
      </joint>
      <joint name='link_2_JOINT_7' type='fixed'>
        <parent>link_2</parent>
        <child>link_3</child>
        <pose>0 0 0 0 -0 0</pose>
        <physics>
          <ode>
            <limit>
              <cfm>0</cfm>
              <erp>0.2</erp>
            </limit>
            <suspension>
              <cfm>0</cfm>
              <erp>0.2</erp>
            </suspension>
          </ode>
        </physics>
      </joint>
      <static>0</static>
      <allow_auto_disable>1</allow_auto_disable>
      <pose>3.59938 1.41015 0.213458 0 -0 0</pose>
    </model>
    <model name='cafe_table'>
      <static>1</static>
      <link name='link'>
        <collision name='surface'>
          <pose>0 0 0.755 0 -0 0</pose>
          <geometry>
            <box>
              <size>0.913 0.913 0.04</size>
            </box>
          </geometry>
          <max_contacts>10</max_contacts>
          <surface>
            <contact>
              <ode/>
            </contact>
            <bounce/>
            <friction>
              <torsional>
                <ode/>
              </torsional>
              <ode/>
            </friction>
          </surface>
        </collision>
        <collision name='column'>
          <pose>0 0 0.37 0 -0 0</pose>
          <geometry>
            <box>
              <size>0.042 0.042 0.74</size>
            </box>
          </geometry>
          <max_contacts>10</max_contacts>
          <surface>
            <contact>
              <ode/>
            </contact>
            <bounce/>
            <friction>
              <torsional>
                <ode/>
              </torsional>
              <ode/>
            </friction>
          </surface>
        </collision>
        <collision name='base'>
          <pose>0 0 0.02 0 -0 0</pose>
          <geometry>
            <box>
              <size>0.56 0.56 0.04</size>
            </box>
          </geometry>
          <max_contacts>10</max_contacts>
          <surface>
            <contact>
              <ode/>
            </contact>
            <bounce/>
            <friction>
              <torsional>
                <ode/>
              </torsional>
              <ode/>
            </friction>
          </surface>
        </collision>
        <visual name='visual'>
          <geometry>
            <mesh>
              <uri>model://cafe_table/meshes/cafe_table.dae</uri>
            </mesh>
          </geometry>
        </visual>
        <self_collide>0</self_collide>
        <enable_wind>0</enable_wind>
        <kinematic>0</kinematic>
      </link>
      <pose>0.655672 -0.222057 0 0 -0 0</pose>
    </model>
    <model name='my_ball'>
      <link name='link_0'>
        <inertial>
          <mass>1</mass>
          <inertia>
            <ixx>0.1</ixx>
            <ixy>0</ixy>
            <ixz>0</ixz>
            <iyy>0.1</iyy>
            <iyz>0</iyz>
            <izz>0.1</izz>
          </inertia>
          <pose>0 0 0 0 -0 0</pose>
        </inertial>
        <pose>0 0 0 0 -0 0</pose>
        <gravity>1</gravity>
        <self_collide>0</self_collide>
        <kinematic>0</kinematic>
        <enable_wind>0</enable_wind>
        <visual name='visual'>
          <pose>0 0 0 0 -0 0</pose>
          <geometry>
            <sphere>
              <radius>0.1</radius>
            </sphere>
          </geometry>
          <material>
            <lighting>1</lighting>
            <script>
              <uri>file://media/materials/scripts/gazebo.material</uri>
              <name>Gazebo/Grey</name>
            </script>
            <shader type='pixel'>
              <normal_map>__default__</normal_map>
            </shader>
            <ambient>1 1 1 1</ambient>
            <diffuse>1 1 1 1</diffuse>
            <specular>1 1 1 1</specular>
            <emissive>1 1 1 1</emissive>
          </material>
          <transparency>0</transparency>
          <cast_shadows>1</cast_shadows>
        </visual>
        <collision name='collision'>
          <laser_retro>0</laser_retro>
          <max_contacts>10</max_contacts>
          <pose>0 0 0 0 -0 0</pose>
          <geometry>
            <sphere>
              <radius>0.1</radius>
            </sphere>
          </geometry>
          <surface>
            <friction>
              <ode>
                <mu>1</mu>
                <mu2>1</mu2>
                <fdir1>0 0 0</fdir1>
                <slip1>0</slip1>
                <slip2>0</slip2>
              </ode>
              <torsional>
                <coefficient>1</coefficient>
                <patch_radius>0</patch_radius>
                <surface_radius>0</surface_radius>
                <use_patch_radius>1</use_patch_radius>
                <ode>
                  <slip>0</slip>
                </ode>
              </torsional>
            </friction>
            <bounce>
              <restitution_coefficient>0</restitution_coefficient>
              <threshold>1e+06</threshold>
            </bounce>
            <contact>
              <collide_without_contact>0</collide_without_contact>
              <collide_without_contact_bitmask>1</collide_without_contact_bitmask>
              <collide_bitmask>1</collide_bitmask>
              <ode>
                <soft_cfm>0</soft_cfm>
                <soft_erp>0.2</soft_erp>
                <kp>1e+13</kp>
                <kd>1</kd>
                <max_vel>0.01</max_vel>
                <min_depth>0</min_depth>
              </ode>
              <bullet>
                <split_impulse>1</split_impulse>
                <split_impulse_penetration_threshold>-0.01</split_impulse_penetration_threshold>
                <soft_cfm>0</soft_cfm>
                <soft_erp>0.2</soft_erp>
                <kp>1e+13</kp>
                <kd>1</kd>
              </bullet>
            </contact>
          </surface>
        </collision>
      </link>
      <static>0</static>
      <allow_auto_disable>1</allow_auto_disable>
      <pose>1.29031 -7.77546 0.5 0 -0 0</pose>
    </model>
  </world>
</sdf>
